from pypy.rpython.lltypesystem import rffi, lltype
from pypy.interpreter.error import OperationError
from pypy.module.cpyext.api import cpython_api, PyObject, make_ref,\
        register_container, CANNOT_FAIL
from pypy.module.cpyext.state import State

@cpython_api([PyObject, PyObject], lltype.Void)
def PyErr_SetObject(space, w_type, w_value):
    """This function is similar to PyErr_SetString() but lets you specify an
    arbitrary Python object for the "value" of the exception."""
    state = space.fromcache(State)
    state.set_exception(w_type, w_value)

@cpython_api([PyObject, rffi.CCHARP], lltype.Void)
def PyErr_SetString(space, w_type, message_ptr):
    message = rffi.charp2str(message_ptr)
    PyErr_SetObject(space, w_type, space.wrap(message))

@cpython_api([], PyObject, borrowed=True)
def PyErr_Occurred(space):
    state = space.fromcache(State)
    register_container(space, lltype.nullptr(PyObject.TO))
    return state.exc_type

@cpython_api([], lltype.Void)
def PyErr_Clear(space):
    state = space.fromcache(State)
    state.clear_exception()

@cpython_api([], lltype.Void)
def PyErr_BadInternalCall(space):
    raise OperationError(space.w_SystemError, space.wrap("Bad internal call!"))

@cpython_api([PyObject, PyObject], rffi.INT_real, error=CANNOT_FAIL)
def PyErr_GivenExceptionMatches(space, w_given, w_exc):
    """Return true if the given exception matches the exception in exc.  If
    exc is a class object, this also returns true when given is an instance
    of a subclass.  If exc is a tuple, all exceptions in the tuple (and
    recursively in subtuples) are searched for a match."""
    if (space.is_true(space.isinstance(w_given, space.w_BaseException)) or
        space.is_oldstyle_instance(w_given)):
        w_given_type = space.exception_getclass(w_given)
    else:
        w_given_type = w_given
    return space.exception_match(w_given_type, w_exc)

@cpython_api([PyObject], rffi.INT_real, error=CANNOT_FAIL)
def PyErr_ExceptionMatches(space, w_exc):
    """Equivalent to PyErr_GivenExceptionMatches(PyErr_Occurred(), exc).  This
    should only be called when an exception is actually set; a memory access
    violation will occur if no exception has been raised."""
    w_type = PyErr_Occurred(space)
    return PyErr_GivenExceptionMatches(space, w_type, w_exc)
